<?xml version="1.0" ?>
<!-- =================================================================================== -->
<!-- |    This document was autogenerated by xacro from doris_description_headless.xacro | -->
<!-- |    EDITING THIS FILE BY HAND IS NOT RECOMMENDED                                 | -->
<!-- =================================================================================== -->
<robot name="doris">
  <link name="base_link">
    <inertial>
      <origin rpy="0 0 0" xyz="-4.0871E-05 -1.3082E-06 0.18"/>
      <mass value="34.858"/>
      <inertia ixx="0.80128" ixy="8.4152E-06" ixz="0.00010815" iyy="1.0005" iyz="3.4516E-06" izz="1.5171"/>
    </inertial>
    <visual>
      <origin rpy="0 0 0" xyz="0 0 0"/>
      <geometry>
        <mesh filename="package://patrolbot_description/meshes/hull.stl" scale="1 1 0.8"/>
      </geometry>
      <material name="">
        <color rgba="0.79216 0.81961 0.93333 1"/>
      </material>
    </visual>
    <collision>
      <origin rpy="0 0 0" xyz="0 0 0"/>
      <geometry>
        <mesh filename="package://patrolbot_description/meshes/hull_collision.stl" scale="1 1 0.8"/>
      </geometry>
    </collision>
  </link>
  <link name="left_wheel_link">
    <inertial>
      <origin rpy="0 0 0" xyz="0.0375 -5.5511E-17 -3.3307E-16"/>
      <mass value="2.1507"/>
      <inertia ixx="0.0099942" ixy="-1.5304E-22" ixz="-9.8205E-20" iyy="0.0058914" iyz="0" izz="0.0058914"/>
    </inertial>
    <visual>
      <origin rpy="0 0 0" xyz="0 0 -0.005"/>
      <geometry>
        <mesh filename="package://patrolbot_description/meshes/left_wheel.stl"/>
      </geometry>
      <material name="">
        <color rgba="0.79216 0.81961 0.93333 1"/>
      </material>
    </visual>
    <collision>
      <origin rpy="0 0 0" xyz="0 0 0"/>
      <geometry>
        <!--<mesh filename="package://patrolbot_description/meshes/left_wheel_link.STL" />-->
        <mesh filename="package://patrolbot_description/meshes/left_wheel_collision.stl"/>
        -
      
      </geometry>
    </collision>
  </link>
  <joint name="left_wheel_joint" type="continuous">
    <origin rpy="1.5672 0 1.5708" xyz="0 0.1415 0.0495"/>
    <parent link="base_link"/>
    <child link="left_wheel_link"/>
    <axis xyz="1 0 0"/>
    <limit effort="200" velocity="6.28"/>
  </joint>
  <link name="right_wheel_link">
    <inertial>
      <origin rpy="0 0 0" xyz="-0.00029672 -1.1102E-16 1.1102E-16"/>
      <mass value="2.1507"/>
      <inertia ixx="0.0099942" ixy="9.0771E-18" ixz="-8.6087E-18" iyy="0.0058914" iyz="0" izz="0.0058914"/>
    </inertial>
    <visual>
      <origin rpy="0 0 0" xyz="0 0 -0.005"/>
      <geometry>
        <mesh filename="package://patrolbot_description/meshes/right_wheel.stl"/>
      </geometry>
      <material name="">
        <color rgba="0.79216 0.81961 0.93333 1"/>
      </material>
    </visual>
    <collision>
      <origin rpy="0 0 0" xyz="0 0 0"/>
      <geometry>
        <!--<mesh filename="package://patrolbot_description/meshes/right_wheel_link.STL" />-->
        <mesh filename="package://patrolbot_description/meshes/right_wheel_collision.stl"/>
      </geometry>
    </collision>
  </link>
  <joint name="right_wheel_joint" type="continuous">
    <origin rpy="0.75508 0 1.5708" xyz="0 -0.1787 0.0495"/>
    <parent link="base_link"/>
    <child link="right_wheel_link"/>
    <axis xyz="1 0 0"/>
    <limit effort="200" velocity="6.28"/>
  </joint>
  <joint name="dorso_arm_base" type="prismatic">
    <parent link="dorso_link"/>
    <child link="vx300s/base_link"/>
    <origin rpy="0 0 0" xyz="0.20 0 0"/>
    <axis xyz="0 0 1"/>
    <limit effort="2000.0" lower="0.02" upper="0.6" velocity="0.5"/>
    <dynamics damping="0.5" friction="0.1"/>
  </joint>
  <material name="interbotix_black">
    <texture filename="package://doris_arm_description/meshes/interbotix_black.png"/>
  </material>
  <link name="vx300s/base_link">
    <visual>
      <origin rpy="0 0 1.5707963267948966" xyz="0 0 0"/>
      <geometry>
        <mesh filename="package://doris_arm_description/meshes/vx300s_meshes/vx300s_1_base.stl" scale="0.001 0.001 0.001"/>
      </geometry>
      <material name="interbotix_black"/>
    </visual>
    <collision>
      <origin rpy="0 0 1.5707963267948966" xyz="0 0 0"/>
      <geometry>
        <mesh filename="package://doris_arm_description/meshes/vx300s_meshes/vx300s_1_base.stl" scale="0.001 0.001 0.001"/>
      </geometry>
    </collision>
    <inertial>
      <origin rpy="0 0 1.5707963267948966" xyz="-0.0534774000 -0.0005625750 0.0205961000"/>
      <mass value="0.969034"/>
      <inertia ixx="0.0060240000" ixy="0.0000471300" ixz="0.0000038510" iyy="0.0017000000" iyz="-0.0000841500" izz="0.0071620000"/>
    </inertial>
  </link>
  <joint name="waist" type="revolute">
    <axis xyz="0 0 1"/>
    <limit effort="10" lower="-3.141582653589793" upper="3.141582653589793" velocity="3.141592653589793"/>
    <origin rpy="0 0 0" xyz="0 0 0.079"/>
    <parent link="vx300s/base_link"/>
    <child link="vx300s/shoulder_link"/>
    <dynamics friction="0.1"/>
  </joint>
  <transmission name="trans_waist">
    <type>transmission_interface/SimpleTransmission</type>
    <joint name="waist">
      <hardwareInterface>hardware_interface/EffortJointInterface</hardwareInterface>
    </joint>
    <actuator name="waist_motor">
      <mechanicalReduction>1</mechanicalReduction>
    </actuator>
  </transmission>
  <link name="vx300s/shoulder_link">
    <visual>
      <origin rpy="0 0 1.5707963267948966" xyz="0 0 -0.003"/>
      <geometry>
        <mesh filename="package://doris_arm_description/meshes/vx300s_meshes/vx300s_2_shoulder.stl" scale="0.001 0.001 0.001"/>
      </geometry>
      <material name="interbotix_black"/>
    </visual>
    <collision>
      <origin rpy="0 0 1.5707963267948966" xyz="0 0 -0.003"/>
      <geometry>
        <mesh filename="package://doris_arm_description/meshes/vx300s_meshes/vx300s_2_shoulder.stl" scale="0.001 0.001 0.001"/>
      </geometry>
    </collision>
    <inertial>
      <origin rpy="0 0 1.5707963267948966" xyz="0.0002592330 -0.0000033552 0.0116129000"/>
      <mass value="0.798614"/>
      <inertia ixx="0.0009388000" ixy="-0.0000000010" ixz="-0.0000000191" iyy="0.0011380000" iyz="0.0000059568" izz="0.0012010000"/>
    </inertial>
  </link>
  <joint name="shoulder" type="revolute">
    <axis xyz="0 1 0"/>
    <limit effort="20" lower="-1.8500490071139892" upper="1.2566370614359172" velocity="3.141592653589793"/>
    <origin rpy="0 0 0" xyz="0 0 0.04805"/>
    <parent link="vx300s/shoulder_link"/>
    <child link="vx300s/upper_arm_link"/>
    <dynamics friction="0.1"/>
  </joint>
  <transmission name="trans_shoulder">
    <type>transmission_interface/SimpleTransmission</type>
    <joint name="shoulder">
      <hardwareInterface>hardware_interface/EffortJointInterface</hardwareInterface>
    </joint>
    <actuator name="shoulder_motor">
      <mechanicalReduction>1</mechanicalReduction>
    </actuator>
  </transmission>
  <link name="vx300s/upper_arm_link">
    <visual>
      <origin rpy="0 0 1.5707963267948966" xyz="0 0 0"/>
      <geometry>
        <mesh filename="package://doris_arm_description/meshes/vx300s_meshes/vx300s_3_upper_arm.stl" scale="0.001 0.001 0.001"/>
      </geometry>
      <material name="interbotix_black"/>
    </visual>
    <collision>
      <origin rpy="0 0 1.5707963267948966" xyz="0 0 0"/>
      <geometry>
        <mesh filename="package://doris_arm_description/meshes/vx300s_meshes/vx300s_3_upper_arm.stl" scale="0.001 0.001 0.001"/>
      </geometry>
    </collision>
    <inertial>
      <origin rpy="0 0 1.5707963267948966" xyz="0.0206949000 0.0000000004 0.2264590000"/>
      <mass value="0.792592"/>
      <inertia ixx="0.0089250000" ixy="0.0000000000" ixz="0.0000000000" iyy="0.0089370000" iyz="0.0012010000" izz="0.0009357000"/>
    </inertial>
  </link>
  <joint name="elbow" type="revolute">
    <axis xyz="0 1 0"/>
    <limit effort="15" lower="-1.7627825445142729" upper="1.6057029118347832" velocity="3.141592653589793"/>
    <origin rpy="0 0 0" xyz="0.05955 0 0.3"/>
    <parent link="vx300s/upper_arm_link"/>
    <child link="vx300s/upper_forearm_link"/>
    <dynamics friction="0.1"/>
  </joint>
  <transmission name="trans_elbow">
    <type>transmission_interface/SimpleTransmission</type>
    <joint name="elbow">
      <hardwareInterface>hardware_interface/EffortJointInterface</hardwareInterface>
    </joint>
    <actuator name="elbow_motor">
      <mechanicalReduction>1</mechanicalReduction>
    </actuator>
  </transmission>
  <link name="vx300s/upper_forearm_link">
    <visual>
      <origin rpy="0 0 0" xyz="0 0 0"/>
      <geometry>
        <mesh filename="package://doris_arm_description/meshes/vx300s_meshes/vx300s_4_upper_forearm.stl" scale="0.001 0.001 0.001"/>
      </geometry>
      <material name="interbotix_black"/>
    </visual>
    <collision>
      <origin rpy="0 0 0" xyz="0 0 0"/>
      <geometry>
        <mesh filename="package://doris_arm_description/meshes/vx300s_meshes/vx300s_4_upper_forearm.stl" scale="0.001 0.001 0.001"/>
      </geometry>
    </collision>
    <inertial>
      <origin rpy="0 0 0" xyz="0.105723 0 0"/>
      <mass value="0.322228"/>
      <inertia ixx="0.0001524000" ixy="-0.0000188300" ixz="-0.0000084064" iyy="0.0013420000" iyz="0.0000012564" izz="0.0014410000"/>
    </inertial>
  </link>
  <joint name="forearm_roll" type="revolute">
    <axis xyz="1 0 0"/>
    <limit effort="2" lower="-3.141582653589793" upper="3.141582653589793" velocity="3.141592653589793"/>
    <origin rpy="0 0 0" xyz="0.2 0 0"/>
    <parent link="vx300s/upper_forearm_link"/>
    <child link="vx300s/lower_forearm_link"/>
    <dynamics friction="0.1"/>
  </joint>
  <transmission name="trans_forearm_roll">
    <type>transmission_interface/SimpleTransmission</type>
    <joint name="forearm_roll">
      <hardwareInterface>hardware_interface/EffortJointInterface</hardwareInterface>
    </joint>
    <actuator name="forearm_roll_motor">
      <mechanicalReduction>1</mechanicalReduction>
    </actuator>
  </transmission>
  <link name="vx300s/lower_forearm_link">
    <visual>
      <origin rpy="3.141592653589793 0 0" xyz="0 0 0"/>
      <geometry>
        <mesh filename="package://doris_arm_description/meshes/vx300s_meshes/vx300s_5_lower_forearm.stl" scale="0.001 0.001 0.001"/>
      </geometry>
      <material name="interbotix_black"/>
    </visual>
    <collision>
      <origin rpy="3.141592653589793 0 0" xyz="0 0 0"/>
      <geometry>
        <mesh filename="package://doris_arm_description/meshes/vx300s_meshes/vx300s_5_lower_forearm.stl" scale="0.001 0.001 0.001"/>
      </geometry>
    </collision>
    <inertial>
      <origin rpy="3.141592653589793 0 0" xyz="0.0513477000 0.0068046200 0"/>
      <mass value="0.414823"/>
      <inertia ixx="0.0001753000" ixy="-0.0000852800" ixz="0" iyy="0.0005269000" iyz="0" izz="0.0005911000"/>
    </inertial>
  </link>
  <joint name="wrist_angle" type="revolute">
    <axis xyz="0 1 0"/>
    <limit effort="5" lower="-1.8675022996339325" upper="2.234021442552742" velocity="3.141592653589793"/>
    <origin rpy="0 0 0" xyz="0.1 0 0"/>
    <parent link="vx300s/lower_forearm_link"/>
    <child link="vx300s/wrist_link"/>
    <dynamics friction="0.1"/>
  </joint>
  <transmission name="trans_wrist_angle">
    <type>transmission_interface/SimpleTransmission</type>
    <joint name="wrist_angle">
      <hardwareInterface>hardware_interface/EffortJointInterface</hardwareInterface>
    </joint>
    <actuator name="wrist_angle_motor">
      <mechanicalReduction>1</mechanicalReduction>
    </actuator>
  </transmission>
  <link name="vx300s/wrist_link">
    <visual>
      <origin rpy="0 0 1.5707963267948966" xyz="0 0 0"/>
      <geometry>
        <mesh filename="package://doris_arm_description/meshes/vx300s_meshes/vx300s_6_wrist.stl" scale="0.001 0.001 0.001"/>
      </geometry>
      <material name="interbotix_black"/>
    </visual>
    <collision>
      <origin rpy="0 0 1.5707963267948966" xyz="0 0 0"/>
      <geometry>
        <mesh filename="package://doris_arm_description/meshes/vx300s_meshes/vx300s_6_wrist.stl" scale="0.001 0.001 0.001"/>
      </geometry>
    </collision>
    <inertial>
      <origin rpy="0 0 1.5707963267948966" xyz="0.0467430000 -0.0000076652 0.0105650000"/>
      <mass value="0.115395"/>
      <inertia ixx="0.0000463100" ixy="0.0000000195" ixz="0.0000000023" iyy="0.0000451400" iyz="0.0000042002" izz="0.0000527000"/>
    </inertial>
  </link>
  <joint name="wrist_rotate" type="revolute">
    <axis xyz="1 0 0"/>
    <limit effort="1" lower="-3.141582653589793" upper="3.141582653589793" velocity="3.141592653589793"/>
    <origin rpy="0 0 0" xyz="0.069744 0 0"/>
    <parent link="vx300s/wrist_link"/>
    <child link="vx300s/gripper_link"/>
    <dynamics friction="0.1"/>
  </joint>
  <transmission name="trans_wrist_rotate">
    <type>transmission_interface/SimpleTransmission</type>
    <joint name="wrist_rotate">
      <hardwareInterface>hardware_interface/EffortJointInterface</hardwareInterface>
    </joint>
    <actuator name="wrist_rotate_motor">
      <mechanicalReduction>1</mechanicalReduction>
    </actuator>
  </transmission>
  <link name="vx300s/gripper_link">
    <visual>
      <origin rpy="0 0 1.5707963267948966" xyz="-0.02 0 0"/>
      <geometry>
        <mesh filename="package://doris_arm_description/meshes/vx300s_meshes/vx300s_7_gripper.stl" scale="0.001 0.001 0.001"/>
      </geometry>
      <material name="interbotix_black"/>
    </visual>
    <collision>
      <origin rpy="0 0 1.5707963267948966" xyz="-0.02 0 0"/>
      <geometry>
        <mesh filename="package://doris_arm_description/meshes/vx300s_meshes/vx300s_7_gripper.stl" scale="0.001 0.001 0.001"/>
      </geometry>
    </collision>
    <inertial>
      <origin rpy="0 0 1.5707963267948966" xyz="0.0230010000 0.0000000000 0.0115230000"/>
      <mass value="0.097666"/>
      <inertia ixx="0.0000326800" ixy="0.0000000000" ixz="0.0000000000" iyy="0.0000243600" iyz="0.0000002785" izz="0.0000211900"/>
    </inertial>
  </link>
  <joint name="ee_arm" type="fixed">
    <axis xyz="1 0 0"/>
    <origin rpy="0 0 0" xyz="0.042825 0 0"/>
    <parent link="vx300s/gripper_link"/>
    <child link="vx300s/ee_arm_link"/>
  </joint>
  <link name="vx300s/ee_arm_link">
    <inertial>
      <mass value="0.001"/>
      <inertia ixx="0.0001" ixy="0" ixz="0" iyy="0.0001" iyz="0" izz="0.0001"/>
    </inertial>
  </link>
  <joint name="gripper" type="continuous">
    <axis xyz="1 0 0"/>
    <limit effort="1" velocity="3.141592653589793"/>
    <origin rpy="0 0 0" xyz="0.005675 0 0"/>
    <parent link="vx300s/ee_arm_link"/>
    <child link="vx300s/gripper_prop_link"/>
    <dynamics friction="0.1"/>
  </joint>
  <transmission name="trans_gripper">
    <type>transmission_interface/SimpleTransmission</type>
    <joint name="gripper">
      <hardwareInterface>hardware_interface/EffortJointInterface</hardwareInterface>
    </joint>
    <actuator name="gripper_motor">
      <mechanicalReduction>1</mechanicalReduction>
    </actuator>
  </transmission>
  <link name="vx300s/gripper_prop_link">
    <visual>
      <origin rpy="0 0 1.5707963267948966" xyz="-0.0685 0 0"/>
      <geometry>
        <mesh filename="package://doris_arm_description/meshes/vx300s_meshes/vx300s_8_gripper_prop.stl" scale="0.001 0.001 0.001"/>
      </geometry>
      <material name="interbotix_black"/>
    </visual>
    <collision>
      <origin rpy="0 0 1.5707963267948966" xyz="-0.0685 0 0"/>
      <geometry>
        <mesh filename="package://doris_arm_description/meshes/vx300s_meshes/vx300s_8_gripper_prop.stl" scale="0.001 0.001 0.001"/>
      </geometry>
    </collision>
    <inertial>
      <origin rpy="0 0 1.5707963267948966" xyz="0.0023780000 0.0000000285 0.0000000000"/>
      <mass value="0.008009"/>
      <inertia ixx="0.0000020386" ixy="0.0000000000" ixz="0.0000006559" iyy="0.0000042979" iyz="0.0000000000" izz="0.0000023796"/>
    </inertial>
  </link>
  <!-- If the AR tag is being used, then add the AR tag mount -->
  <!-- If the gripper bar is being used, then also add the gripper bar -->
  <joint name="gripper_bar" type="fixed">
    <axis xyz="1 0 0"/>
    <origin rpy="0 0 0" xyz="0 0 0"/>
    <parent link="vx300s/ee_arm_link"/>
    <child link="vx300s/gripper_bar_link"/>
  </joint>
  <link name="vx300s/gripper_bar_link">
    <visual>
      <origin rpy="0 0 1.5707963267948966" xyz="-0.063 0 0"/>
      <geometry>
        <mesh filename="package://doris_arm_description/meshes/vx300s_meshes/vx300s_9_gripper_bar.stl" scale="0.001 0.001 0.001"/>
      </geometry>
      <material name="interbotix_black"/>
    </visual>
    <collision>
      <origin rpy="0 0 1.5707963267948966" xyz="-0.063 0 0"/>
      <geometry>
        <mesh filename="package://doris_arm_description/meshes/vx300s_meshes/vx300s_9_gripper_bar.stl" scale="0.001 0.001 0.001"/>
      </geometry>
    </collision>
    <inertial>
      <origin rpy="0 0 1.5707963267948966" xyz="0.0067940000 -0.0000004272 -0.0007760000"/>
      <mass value="0.150986"/>
      <inertia ixx="0.0000789500" ixy="-0.0000000012" ixz="0.0000001341" iyy="0.0003283000" iyz="0.0000017465" izz="0.0003095000"/>
    </inertial>
  </link>
  <joint name="ee_bar" type="fixed">
    <axis xyz="1 0 0"/>
    <origin rpy="0 0 0" xyz="0.025875 0 0"/>
    <parent link="vx300s/gripper_bar_link"/>
    <child link="vx300s/fingers_link"/>
  </joint>
  <link name="vx300s/fingers_link">
    <inertial>
      <mass value="0.001"/>
      <inertia ixx="0.0001" ixy="0" ixz="0" iyy="0.0001" iyz="0" izz="0.0001"/>
    </inertial>
  </link>
  <!-- If the gripper fingers are being used, add those as well -->
  <joint name="left_finger" type="prismatic">
    <axis xyz="0 1 0"/>
    <limit effort="5" lower="0.021" upper="0.057" velocity="1"/>
    <origin rpy="0 0 0" xyz="0 0 0"/>
    <parent link="vx300s/fingers_link"/>
    <child link="vx300s/left_finger_link"/>
    <dynamics friction="0.1"/>
  </joint>
  <transmission name="trans_left_finger">
    <type>transmission_interface/SimpleTransmission</type>
    <joint name="left_finger">
      <hardwareInterface>hardware_interface/EffortJointInterface</hardwareInterface>
    </joint>
    <actuator name="left_finger_motor">
      <mechanicalReduction>1</mechanicalReduction>
    </actuator>
  </transmission>
  <link name="vx300s/left_finger_link">
    <visual>
      <origin rpy="1.5707963267948966 -3.141592653589793 1.5707963267948966" xyz="-0.0404 -0.0575 0"/>
      <geometry>
        <mesh filename="package://doris_arm_description/meshes/vx300s_meshes/vx300s_10_gripper_finger.stl" scale="0.001 0.001 0.001"/>
      </geometry>
      <material name="interbotix_black"/>
    </visual>
    <collision>
      <origin rpy="1.5707963267948966 -3.141592653589793 1.5707963267948966" xyz="-0.0404 -0.0575 0"/>
      <geometry>
        <mesh filename="package://doris_arm_description/meshes/vx300s_meshes/vx300s_10_gripper_finger.stl" scale="0.001 0.001 0.001"/>
      </geometry>
    </collision>
    <inertial>
      <origin rpy="3.141592653589793 3.141592653589793 1.5707963267948966" xyz="0.0173440000 -0.0060692000 0.0000000000"/>
      <mass value="0.034796"/>
      <inertia ixx="0.0000243300" ixy="-0.0000024004" ixz="0.0000000000" iyy="0.0000125500" iyz="0.0000000000" izz="0.0000141700"/>
    </inertial>
  </link>
  <joint name="right_finger" type="prismatic">
    <axis xyz="0 1 0"/>
    <limit effort="5" lower="-0.057" upper="-0.021" velocity="1"/>
    <origin rpy="0 0 0" xyz="0 0 0"/>
    <parent link="vx300s/fingers_link"/>
    <child link="vx300s/right_finger_link"/>
    <dynamics friction="0.1"/>
    <mimic joint="left_finger" multiplier="-1" offset="0"/>
  </joint>
  <transmission name="trans_right_finger">
    <type>transmission_interface/SimpleTransmission</type>
    <joint name="right_finger">
      <hardwareInterface>hardware_interface/EffortJointInterface</hardwareInterface>
    </joint>
    <actuator name="right_finger_motor">
      <mechanicalReduction>1</mechanicalReduction>
    </actuator>
  </transmission>
  <link name="vx300s/right_finger_link">
    <visual>
      <origin rpy="-1.5707963267948966 3.141592653589793 -1.5707963267948966" xyz="-0.0404 0.0575 0 "/>
      <geometry>
        <mesh filename="package://doris_arm_description/meshes/vx300s_meshes/vx300s_10_gripper_finger.stl" scale="0.001 0.001 0.001"/>
      </geometry>
      <material name="interbotix_black"/>
    </visual>
    <collision>
      <origin rpy="-1.5707963267948966 3.141592653589793 -1.5707963267948966" xyz="-0.0404 0.0575 0 "/>
      <geometry>
        <mesh filename="package://doris_arm_description/meshes/vx300s_meshes/vx300s_10_gripper_finger.stl" scale="0.001 0.001 0.001"/>
      </geometry>
    </collision>
    <inertial>
      <origin rpy="0 3.141592653589793 1.5707963267948966" xyz="0.0173440000 0.0060692000  0.0000000000"/>
      <mass value="0.034796"/>
      <inertia ixx="0.0000243300" ixy="0.0000024001" ixz="0.0000000000" iyy="0.0000125500" iyz="0.0000000000" izz="0.0000141700"/>
    </inertial>
  </link>
  <joint name="ee_gripper" type="fixed">
    <axis xyz="1 0 0"/>
    <origin rpy="0 0 0" xyz="0.0385 0 0"/>
    <parent link="vx300s/fingers_link"/>
    <child link="vx300s/ee_gripper_link"/>
  </joint>
  <link name="vx300s/ee_gripper_link">
    <inertial>
      <mass value="0.001"/>
      <inertia ixx="0.0001" ixy="0" ixz="0" iyy="0.0001" iyz="0" izz="0.0001"/>
    </inertial>
  </link>
  <link name="dorso_link">
    <inertial>
      <origin rpy="0 0 0" xyz="-0.049721 -0.0015664 0.52098"/>
      <mass value="5.8385"/>
      <inertia ixx="0.23511" ixy="2.2795E-05" ixz="0.00021828" iyy="0.24015" iyz="2.7987E-05" izz="0.022627"/>
    </inertial>
    <visual>
      <origin rpy="0 0 0" xyz="0 0 0"/>
      <geometry>
        <mesh filename="package://doris_dorso_description/meshes/dorso_link.stl"/>
      </geometry>
      <material name="">
        <color rgba="0.79216 0.81961 0.93333 1"/>
      </material>
    </visual>
    <collision>
      <origin rpy="0 0 0" xyz="0 0 0"/>
      <geometry>
        <mesh filename="package://doris_dorso_description/meshes/dorso_collision.stl"/>
      </geometry>
    </collision>
  </link>
  <!--xacro:include filename="$(find kinect2_description)/urdf/kinect2_description.urdf.xacro" /-->
  <link name="base_footprint"/>
  <joint name="base_joint" type="fixed">
    <child link="base_link"/>
    <parent link="base_footprint"/>
  </joint>
  <!--link name="gripper_ir_link"></link>
    <joint name="gripper_ir_joint" type="fixed">
        <child link="gripper_ir_link"/>
        <parent link="gripper_link"/>
        <origin xyz="0.02 0 -0.01" rpy="0 1.57 0"/>
    </joint-->
  <link name="frontal_caster_link">
    <inertial>
      <origin rpy="0 0 0" xyz="0 0 0"/>
      <mass value="0.1"/>
      <inertia ixx="0.001" ixy="0" ixz="0" iyy="0.001" iyz="0" izz="0.001"/>
    </inertial>
    <collision>
      <origin rpy="0 0 0" xyz="0 0 0"/>
      <geometry>
        <sphere radius="0.05"/>
      </geometry>
    </collision>
  </link>
  <joint name="frontal_caster_joint" type="fixed">
    <parent link="base_link"/>
    <child link="frontal_caster_link"/>
    <origin rpy="0 0 0" xyz="0.2 0 0"/>
  </joint>
  <link name="rear_caster_link">
    <inertial>
      <origin rpy="0 0 0" xyz="0 0 0"/>
      <mass value="0.1"/>
      <inertia ixx="0.001" ixy="0" ixz="0" iyy="0.001" iyz="0" izz="0.001"/>
    </inertial>
    <collision>
      <origin rpy="0 0 0" xyz="0 0 0"/>
      <geometry>
        <sphere radius="0.05"/>
      </geometry>
    </collision>
  </link>
  <joint name="rear_caster_joint" type="fixed">
    <parent link="base_link"/>
    <child link="rear_caster_link"/>
    <origin rpy="0 0 0" xyz="-0.2 0 0"/>
  </joint>
  <!--
    <xacro:hand ns="doris" rpy="0 0 1.570" xyz="0 0 0.1" connected_to="roll_2_link" safety_distance="0.00" use_cylinder_collision_model="false" />
    -->
  <joint name="base_link_dorso" type="fixed">
    <parent link="base_link"/>
    <child link="dorso_link"/>
    <origin rpy="0 0 0" xyz="0 0 0.28"/>
  </joint>
  <!--joint name="dorso_kinect" type="fixed">
        <parent link="dorso_link" />
        <child link="kinect_link" />
        <origin xyz="-0.18 0 0.01" rpy="0 ${3.1416/2} 3.1416" />
    </joint-->
  <!--xacro:sensor_kinect prefix="" name="kinect" parent="dorso_link" cam_px="-0.18" cam_py="0" cam_pz="0.01" cam_or="${-3.1416/2}" cam_op="0" cam_oy="${3.1416/2}"></xacro:sensor_kinect-->
  <!--
    <xacro:realsense_d435_camera_with_mount name="realsense" parent="roll_2_link">
        <origin xyz="0 0.03 0.1" rpy="-1.570 -1.570 0" />
    </xacro:realsense_d435_camera_with_mount>
    -->
  <!--joint name="dorso_hokuyo" type="fixed">
        <parent link="dorso_link" />
        <child link="hokuyo_link" />
        <origin xyz="-0.25 -0.7 0.01" rpy="${3.1416/2} ${-3.1416/2} 3.1416" />
    </joint-->
  <transmission name="trans_left_wheel_joint">
    <type>transmission_interface/SimpleTransmission</type>
    <joint name="left_wheel_joint">
      <hardwareInterface>hardware_interface/EffortJointInterface</hardwareInterface>
    </joint>
    <actuator name="left_wheel_joint_motor">
      <hardwareInterface>hardware_interface/EffortJointInterface</hardwareInterface>
      <mechanicalReduction>1</mechanicalReduction>
    </actuator>
  </transmission>
  <transmission name="trans_dorso_arm_base_joint">
    <type>transmission_interface/SimpleTransmission</type>
    <joint name="dorso_arm_base">
      <hardwareInterface>hardware_interface/EffortJointInterface</hardwareInterface>
    </joint>
    <actuator name="dorso_arm_linear_actuator">
      <hardwareInterface>hardware_interface/EffortJointInterface</hardwareInterface>
      <mechanicalReduction>1</mechanicalReduction>
    </actuator>
  </transmission>
  <transmission name="trans_right_wheel_joint">
    <type>transmission_interface/SimpleTransmission</type>
    <joint name="right_wheel_joint">
      <hardwareInterface>hardware_interface/EffortJointInterface</hardwareInterface>
    </joint>
    <actuator name="right_wheel_joint_motor">
      <hardwareInterface>hardware_interface/EffortJointInterface</hardwareInterface>
      <mechanicalReduction>1</mechanicalReduction>
    </actuator>
  </transmission>
  <transmission name="trans_shoulder_joint">
    <type>transmission_interface/SimpleTransmission</type>
    <joint name="shoulder_joint">
      <hardwareInterface>hardware_interface/EffortJointInterface</hardwareInterface>
    </joint>
    <actuator name="shoulder_joint_motor">
      <hardwareInterface>hardware_interface/EffortJointInterface</hardwareInterface>
      <mechanicalReduction>1</mechanicalReduction>
    </actuator>
  </transmission>
  <transmission name="trans_forearm_shoulder_joint">
    <type>transmission_interface/SimpleTransmission</type>
    <joint name="forearm_shoulder_joint">
      <hardwareInterface>hardware_interface/EffortJointInterface</hardwareInterface>
    </joint>
    <actuator name="forearm_shoulder_joint_motor">
      <hardwareInterface>hardware_interface/EffortJointInterface</hardwareInterface>
      <mechanicalReduction>1</mechanicalReduction>
    </actuator>
  </transmission>
  <transmission name="trans_elbow_joint">
    <type>transmission_interface/SimpleTransmission</type>
    <joint name="elbow_joint">
      <hardwareInterface>hardware_interface/EffortJointInterface</hardwareInterface>
    </joint>
    <actuator name="elbow_joint_motor">
      <hardwareInterface>hardware_interface/EffortJointInterface</hardwareInterface>
      <mechanicalReduction>1</mechanicalReduction>
    </actuator>
  </transmission>
  <transmission name="trans_roll_joint">
    <type>transmission_interface/SimpleTransmission</type>
    <joint name="roll_joint">
      <hardwareInterface>hardware_interface/EffortJointInterface</hardwareInterface>
    </joint>
    <actuator name="roll_joint_motor">
      <hardwareInterface>hardware_interface/EffortJointInterface</hardwareInterface>
      <mechanicalReduction>1</mechanicalReduction>
    </actuator>
  </transmission>
  <transmission name="trans_yaw_joint">
    <type>transmission_interface/SimpleTransmission</type>
    <joint name="yaw_joint">
      <hardwareInterface>hardware_interface/EffortJointInterface</hardwareInterface>
    </joint>
    <actuator name="yaw_joint_motor">
      <hardwareInterface>hardware_interface/EffortJointInterface</hardwareInterface>
      <mechanicalReduction>1</mechanicalReduction>
    </actuator>
  </transmission>
  <transmission name="trans_roll_2_joint">
    <type>transmission_interface/SimpleTransmission</type>
    <joint name="roll_2_joint">
      <hardwareInterface>hardware_interface/EffortJointInterface</hardwareInterface>
    </joint>
    <actuator name="roll_2_joint_motor">
      <hardwareInterface>hardware_interface/EffortJointInterface</hardwareInterface>
      <mechanicalReduction>1</mechanicalReduction>
    </actuator>
  </transmission>
  <!--
    <transmission name="trans_doris_finger_joint1">
        <type>transmission_interface/SimpleTransmission</type>
        <joint name="doris_finger_joint1">
            <hardwareInterface>hardware_interface/EffortJointInterface</hardwareInterface>
        </joint>
        <actuator name="doris_finger_joint1_motor">
            <hardwareInterface>hardware_interface/EffortJointInterface</hardwareInterface>
            <mechanicalReduction>1</mechanicalReduction>
        </actuator>
    </transmission>
    <transmission name="trans_doris_finger_joint2">
        <type>transmission_interface/SimpleTransmission</type>
        <joint name="doris_finger_joint2">
            <hardwareInterface>hardware_interface/EffortJointInterface</hardwareInterface>
        </joint>
        <actuator name="doris_finger_joint2_motor">
            <hardwareInterface>hardware_interface/EffortJointInterface</hardwareInterface>
            <mechanicalReduction>1</mechanicalReduction>
        </actuator>
    </transmission>-->
  <transmission name="trans_left_finger_joint">
    <type>transmission_interface/SimpleTransmission</type>
    <joint name="left_finger_joint">
      <hardwareInterface>hardware_interface/EffortJointInterface</hardwareInterface>
    </joint>
    <actuator name="left_finger_joint_motor">
      <hardwareInterface>hardware_interface/EffortJointInterface</hardwareInterface>
      <mechanicalReduction>1</mechanicalReduction>
    </actuator>
  </transmission>
  <transmission name="trans_right_finger_joint">
    <type>transmission_interface/SimpleTransmission</type>
    <joint name="right_finger_joint">
      <hardwareInterface>hardware_interface/EffortJointInterface</hardwareInterface>
    </joint>
    <actuator name="right_finger_joint_motor">
      <hardwareInterface>hardware_interface/EffortJointInterface</hardwareInterface>
      <mechanicalReduction>1</mechanicalReduction>
    </actuator>
  </transmission>
  <gazebo>
    <plugin filename="libgazebo_ros_control.so" name="gazebo_ros_control">
      <robotNamespace>/</robotNamespace>
    </plugin>
  </gazebo>
  <transmission name="trans_left_wheel_joint">
    <type>transmission_interface/SimpleTransmission</type>
    <joint name="left_wheel_joint">
      <hardwareInterface>hardware_interface/EffortJointInterface</hardwareInterface>
    </joint>
    <actuator name="left_wheel_joint_motor">
      <hardwareInterface>hardware_interface/EffortJointInterface</hardwareInterface>
      <mechanicalReduction>1</mechanicalReduction>
    </actuator>
  </transmission>
  <transmission name="trans_right_wheel_joint">
    <type>transmission_interface/SimpleTransmission</type>
    <joint name="right_wheel_joint">
      <hardwareInterface>hardware_interface/EffortJointInterface</hardwareInterface>
    </joint>
    <actuator name="right_wheel_joint_motor">
      <hardwareInterface>hardware_interface/EffortJointInterface</hardwareInterface>
      <mechanicalReduction>1</mechanicalReduction>
    </actuator>
  </transmission>
  <gazebo>
    <plugin filename="libgazebo_ros_diff_drive.so" name="differential_drive_controller">
      <!-- Plugin update rate in Hz -->
      <updateRate>50</updateRate>
      <!-- Name of left joint, defaults to `left_joint` -->
      <leftJoint>left_wheel_joint</leftJoint>
      <!-- Name of right joint, defaults to `right_joint` -->
      <rightJoint>right_wheel_joint</rightJoint>
      <!-- The distance from the center of one wheel to the other, in meters, defaults to 0.34 m -->
      <wheelSeparation>0.31</wheelSeparation>
      <!-- Diameter of the wheels, in meters, defaults to 0.15 m -->
      <wheelDiameter>0.2</wheelDiameter>
      <!-- Wheel acceleration, in rad/s^2, defaults to 0.0 rad/s^2 -->
      <wheelAcceleration>1.0</wheelAcceleration>
      <!-- Maximum torque which the wheels can produce, in Nm, defaults to 5 Nm -->
      <wheelTorque>20</wheelTorque>
      <!-- Topic to receive geometry_msgs/Twist message commands, defaults to `cmd_vel` -->
      <commandTopic>cmd_vel</commandTopic>
      <!-- Topic to publish nav_msgs/Odometry messages, defaults to `odom` -->
      <odometryTopic>odom</odometryTopic>
      <!-- Odometry frame, defaults to `odom` -->
      <odometryFrame>odom</odometryFrame>
      <!-- Robot frame to calculate odometry from, defaults to `base_footprint` -->
      <robotBaseFrame>base_footprint</robotBaseFrame>
      <!-- Odometry source, 0 for ENCODER, 1 for WORLD, defaults to WORLD -->
      <odometrySource>1</odometrySource>
      <!-- Set to true to publish transforms for the wheel links, defaults to false -->
      <publishWheelTF>false</publishWheelTF>
      <!-- Set to true to publish transforms for the odometry, defaults to true -->
      <publishOdom>true</publishOdom>
      <!-- Set to true to publish sensor_msgs/JointState on /joint_states for the wheel joints, defaults to false -->
      <publishWheelJointState>false</publishWheelJointState>
      <!-- Set to true to swap right and left wheels, defaults to true -->
      <legacyMode>false</legacyMode>
    </plugin>
  </gazebo>
  <material name="gray_material">
    <color rgba="0.5 0.5 0.5 1.0"/>
  </material>
  <material name="black_material">
    <color rgba="0.1 0.1 0.1 1.0"/>
  </material>
  <gazebo reference="base_link">
    <material>Gazebo/Gray</material>
  </gazebo>
  <gazebo reference="left_wheel_link">
    <material>Gazebo/DarkGray</material>
    <mu1>0.2</mu1>
    <mu2>0.2</mu2>
  </gazebo>
  <gazebo reference="right_wheel_link">
    <material>Gazebo/DarkGray</material>
    <mu1>0.2</mu1>
    <mu2>0.2</mu2>
  </gazebo>
  <gazebo reference="frontal_caster_link">
    <mu1>0.0001</mu1>
    <mu2>0.0001</mu2>
  </gazebo>
  <gazebo reference="rear_caster_link">
    <mu1>0.0001</mu1>
    <mu2>0.0001</mu2>
  </gazebo>
  <gazebo reference="dorso_link">
    <material>Gazebo/DarkGray</material>
  </gazebo>
  <gazebo reference="arm_base_link">
    <material>Gazebo/DarkGray</material>
  </gazebo>
  <gazebo reference="shoulder_link">
    <material>Gazebo/DarkGray</material>
  </gazebo>
  <gazebo reference="forearm_link">
    <material>Gazebo/DarkGray</material>
  </gazebo>
  <gazebo reference="elbow_link">
    <material>Gazebo/DarkGray</material>
  </gazebo>
  <gazebo reference="roll_link">
    <material>Gazebo/DarkGray</material>
  </gazebo>
  <gazebo reference="yaw_link">
    <material>Gazebo/DarkGray</material>
  </gazebo>
  <gazebo reference="roll_2_link">
    <material>Gazebo/DarkGray</material>
  </gazebo>
  <gazebo reference="gripper_link">
    <material>Gazebo/DarkGray</material>
    <mu1>10000.0</mu1>
    <mu2>100000.0</mu2>
    <min_depth>0.1</min_depth>
  </gazebo>
  <gazebo reference="left_finger_link">
    <material>Gazebo/Gray</material>
    <mu1>10000.0</mu1>
    <mu2>100000.0</mu2>
    <min_depth>0.1</min_depth>
  </gazebo>
  <gazebo reference="right_finger_link">
    <material>Gazebo/Gray</material>
    <mu1>10000.0</mu1>
    <mu2>100000.0</mu2>
    <min_depth>0.1</min_depth>
  </gazebo>
  <!--gazebo>
        <plugin name="gazebo_grasp_fix" filename="libgazebo_grasp_fix.so">
            <arm>
                <arm_name>arm</arm_name>
                <palm_link>roll_2_link</palm_link>
                <gripper_link>left_finger_link</gripper_link>
                <gripper_link>right_finger_link</gripper_link>
            </arm>
            <forces_angle_tolerance>100</forces_angle_tolerance>
            <update_rate>4</update_rate>
            <grip_count_threshold>4</grip_count_threshold>
            <max_grip_count>4</max_grip_count>
            <release_tolerance>0.005</release_tolerance>
            <disable_collisions_on_attach>false</disable_collisions_on_attach>
            <contact_topic>__default_topic__</contact_topic>
        </plugin>
    </gazeb-->
  <gazebo reference="gripper_ir_link">
    <sensor name="ir_gripper" type="ray">
      <pose>0 0 0 0 0 0</pose>
      <update_rate>50</update_rate>
      <ray>
        <scan>
          <horizontal>
            <samples>1</samples>
            <resolution>1.0</resolution>
            <min_angle>-0.08</min_angle>
            <max_angle>0.08</max_angle>
          </horizontal>
          <vertical>
            <samples>1</samples>
            <resolution>1</resolution>
            <min_angle>-0.04</min_angle>
            <max_angle>0.04</max_angle>
          </vertical>
        </scan>
        <range>
          <min>0.01</min>
          <max>1.5</max>
          <resolution>0.002</resolution>
        </range>
      </ray>
      <plugin filename="libgazebo_ros_range.so" name="gazebo_ros_range">
        <selfCollide>false</selfCollide>
        <alwaysOn>true</alwaysOn>
        <updateRate>5</updateRate>
        <topicName>/gripper/range</topicName>
        <frameName>ir_gripper</frameName>
        <visualize>false</visualize>
        <radiation>infrared</radiation>
        <fov>0.8</fov>
      </plugin>
    </sensor>
  </gazebo>
  <gazebo reference="left_finger_link">
    <sensor name="left_finger_bumper" type="contact">
      <selfCollide>false</selfCollide>
      <alwaysOn>true</alwaysOn>
      <updateRate>50.0</updateRate>
      <contact>
        <collision>left_finger_link_collision</collision>
      </contact>
      <plugin filename="libgazebo_ros_bumper.so" name="left_finger_ros_bumper_controller">
        <bumperTopicName>/gripper/contact/left</bumperTopicName>
        <frameName>world</frameName>
      </plugin>
    </sensor>
  </gazebo>
  <gazebo reference="right_finger_link">
    <sensor name="right_finger_bumper" type="contact">
      <selfCollide>false</selfCollide>
      <alwaysOn>true</alwaysOn>
      <updateRate>50.0</updateRate>
      <contact>
        <collision>right_finger_link_collision</collision>
      </contact>
      <plugin filename="libgazebo_ros_bumper.so" name="right_finger_ros_bumper_controller">
        <bumperTopicName>/gripper/contact/right</bumperTopicName>
        <frameName>world</frameName>
      </plugin>
    </sensor>
  </gazebo>
  <!--
    <gazebo reference="doris_hand">
        <material>Gazebo/DarkGray</material>
    </gazebo>
    <gazebo reference="doris_leftfinger">
        <material>Gazebo/Gray</material>
        <mu1>100.0</mu1>
        <mu2>100.0</mu2>
    </gazebo>
    <gazebo reference="doris_rightfinger">
        <material>Gazebo/Gray</material>
        <mu1>100.0</mu1>
        <mu2>100.0</mu2>
    </gazebo>-->
</robot>

