<?xml version="1.0" ?>
<!-- =================================================================================== -->
<!-- |    This document was autogenerated by xacro from doris_description.urdf.xacro   | -->
<!-- |    EDITING THIS FILE BY HAND IS NOT RECOMMENDED                                 | -->
<!-- =================================================================================== -->
<robot name="doris">
  <link name="base_link">
    <inertial>
      <origin rpy="0 0 0" xyz="-4.0871E-05 -1.3082E-06 0.18"/>
      <mass value="34.858"/>
      <inertia ixx="0.80128" ixy="8.4152E-06" ixz="0.00010815" iyy="1.0005" iyz="3.4516E-06" izz="1.5171"/>
    </inertial>
    <visual>
      <origin rpy="0 0 0" xyz="0 0 0"/>
      <geometry>
        <mesh filename="package://patrolbot_description/meshes/hull.stl" scale="1 1 0.8"/>
      </geometry>
      <material name="">
        <color rgba="0.79216 0.81961 0.93333 1"/>
      </material>
    </visual>
    <collision>
      <origin rpy="0 0 0" xyz="0 0 0"/>
      <geometry>
        <mesh filename="package://patrolbot_description/meshes/hull.stl" scale="1 1 0.8"/>
      </geometry>
    </collision>
  </link>
  <link name="left_wheel_link">
    <inertial>
      <origin rpy="0 0 0" xyz="0.0375 -5.5511E-17 -3.3307E-16"/>
      <mass value="2.1507"/>
      <inertia ixx="0.0099942" ixy="-1.5304E-22" ixz="-9.8205E-20" iyy="0.0058914" iyz="0" izz="0.0058914"/>
    </inertial>
    <visual>
      <origin rpy="0 0 0" xyz="0 0 -0.005"/>
      <geometry>
        <mesh filename="package://patrolbot_description/meshes/left_wheel.stl"/>
      </geometry>
      <material name="">
        <color rgba="0.79216 0.81961 0.93333 1"/>
      </material>
    </visual>
    <collision>
      <origin rpy="0 0 0" xyz="0 0 0"/>
      <geometry>
        <mesh filename="package://patrolbot_description/meshes/left_wheel_link.STL"/>
      </geometry>
    </collision>
  </link>
  <joint name="left_wheel_joint" type="continuous">
    <origin rpy="1.5672 0 1.5708" xyz="0 0.1415 0.0495"/>
    <parent link="base_link"/>
    <child link="left_wheel_link"/>
    <axis xyz="1 0 0"/>
    <limit effort="200" velocity="6.28"/>
  </joint>
  <link name="right_wheel_link">
    <inertial>
      <origin rpy="0 0 0" xyz="-0.00029672 -1.1102E-16 1.1102E-16"/>
      <mass value="2.1507"/>
      <inertia ixx="0.0099942" ixy="9.0771E-18" ixz="-8.6087E-18" iyy="0.0058914" iyz="0" izz="0.0058914"/>
    </inertial>
    <visual>
      <origin rpy="0 0 0" xyz="0 0 -0.005"/>
      <geometry>
        <mesh filename="package://patrolbot_description/meshes/right_wheel.stl"/>
      </geometry>
      <material name="">
        <color rgba="0.79216 0.81961 0.93333 1"/>
      </material>
    </visual>
    <collision>
      <origin rpy="0 0 0" xyz="0 0 0"/>
      <geometry>
        <mesh filename="package://patrolbot_description/meshes/right_wheel_link.STL"/>
      </geometry>
    </collision>
  </link>
  <joint name="right_wheel_joint" type="continuous">
    <origin rpy="0.75508 0 1.5708" xyz="0 -0.1787 0.0495"/>
    <parent link="base_link"/>
    <child link="right_wheel_link"/>
    <axis xyz="1 0 0"/>
    <limit effort="200" velocity="6.28"/>
  </joint>
  <link name="arm_base_link">
    <inertial>
      <origin rpy="0 0 0" xyz="0.0032335 -3.6289E-06 0.02346"/>
      <mass value="0.086496"/>
      <inertia ixx="0.002" ixy="0.0" ixz="0.0" iyy="0.002" iyz="0.0" izz="0.002"/>
    </inertial>
    <visual>
      <origin rpy="0 0 0" xyz="0 0 0"/>
      <geometry>
        <mesh filename="package://doris_arm_description/meshes/arm_base_link.STL"/>
      </geometry>
      <material name="">
        <color rgba="0.79216 0.81961 0.93333 1"/>
      </material>
    </visual>
    <collision>
      <origin rpy="0 0 0" xyz="0 0 0"/>
      <geometry>
        <mesh filename="package://doris_arm_description/meshes/arm_base_link.STL"/>
      </geometry>
    </collision>
  </link>
  <link name="shoulder_link">
    <inertial>
      <origin rpy="0 0 0" xyz="1.80019426116503E-06 0.0469908207821207 1.02798098779305E-05"/>
      <mass value="0.187371975468428"/>
      <inertia ixx="0.002" ixy="0.0" ixz="0.0" iyy="0.002" iyz="0.0" izz="0.002"/>
    </inertial>
    <visual>
      <origin rpy="0 0 0" xyz="0 0 0"/>
      <geometry>
        <mesh filename="package://doris_arm_description/meshes/shoulder_link.STL"/>
      </geometry>
      <material name="">
        <color rgba="0.792156862745098 0.819607843137255 0.933333333333333 1"/>
      </material>
    </visual>
    <collision>
      <origin rpy="0 0 0" xyz="0 0 0"/>
      <geometry>
        <mesh filename="package://doris_arm_description/meshes/shoulder_link.STL"/>
      </geometry>
    </collision>
  </link>
  <joint name="shoulder_joint" type="continuous">
    <origin rpy="1.5708 0 0" xyz="0.018961 0 0.049"/>
    <parent link="arm_base_link"/>
    <child link="shoulder_link"/>
    <axis xyz="0 1 0"/>
    <limit effort="8.4" velocity="6.28"/>
    <dynamics damping="0.7" friction="1.0"/>
  </joint>
  <link name="forearm_link">
    <inertial>
      <origin rpy="0 0 0" xyz="-1.08638707938674E-05 0.145957509942709 0.00428434606455026"/>
      <mass value="0.0731491894717436"/>
      <inertia ixx="0.002" ixy="0.0" ixz="0.0" iyy="0.002" iyz="0.0" izz="0.002"/>
    </inertial>
    <visual>
      <origin rpy="0 0 0" xyz="0 0 0"/>
      <geometry>
        <mesh filename="package://doris_arm_description/meshes/forearm_link.STL"/>
      </geometry>
      <material name="">
        <color rgba="0.792156862745098 0.819607843137255 0.933333333333333 1"/>
      </material>
    </visual>
    <collision>
      <origin rpy="0 0 0" xyz="0 0 0"/>
      <geometry>
        <mesh filename="package://doris_arm_description/meshes/forearm_link.STL"/>
      </geometry>
    </collision>
  </link>
  <joint name="forearm_shoulder_joint" type="continuous">
    <origin rpy="0.93003 1.5708 -0.7" xyz="0 0.0656 0"/>
    <parent link="shoulder_link"/>
    <child link="forearm_link"/>
    <axis xyz="1 0 0"/>
    <limit effort="16.8" velocity="6.28"/>
    <dynamics damping="0.7" friction="1.0"/>
  </joint>
  <link name="elbow_link">
    <inertial>
      <origin rpy="0 0 0" xyz="-3.11104449999267E-05 -0.0168263295023695 0.000457294178247414"/>
      <mass value="0.0892046248471317"/>
      <inertia ixx="0.002" ixy="0.0" ixz="0.0" iyy="0.002" iyz="0.0" izz="0.002"/>
    </inertial>
    <visual>
      <origin rpy="0 0 0" xyz="0 0 0"/>
      <geometry>
        <mesh filename="package://doris_arm_description/meshes/elbow_link.STL"/>
      </geometry>
      <material name="">
        <color rgba="0.792156862745098 0.819607843137255 0.933333333333333 1"/>
      </material>
    </visual>
    <collision>
      <origin rpy="0 0 0" xyz="0 0 0"/>
      <geometry>
        <mesh filename="package://doris_arm_description/meshes/elbow_link.STL"/>
      </geometry>
    </collision>
  </link>
  <joint name="elbow_joint" type="continuous">
    <origin rpy="1.5708 -0.74886 -1.5708" xyz="0 0.30821 -0.040455"/>
    <parent link="forearm_link"/>
    <child link="elbow_link"/>
    <axis xyz="0 0 1"/>
    <limit effort="8.4" velocity="6.28"/>
    <dynamics damping="0.7" friction="1.0"/>
  </joint>
  <link name="roll_link">
    <inertial>
      <origin rpy="0 0 0" xyz="1.19120197594746E-08 -0.010083697233814 -0.0945595691856148"/>
      <mass value="0.108644948048519"/>
      <inertia ixx="0.002" ixy="0.0" ixz="0.0" iyy="0.002" iyz="0.0" izz="0.002"/>
    </inertial>
    <visual>
      <origin rpy="0 0 0" xyz="0 0 0"/>
      <geometry>
        <mesh filename="package://doris_arm_description/meshes/roll_link.STL"/>
      </geometry>
      <material name="">
        <color rgba="0.792156862745098 0.819607843137255 0.933333333333333 1"/>
      </material>
    </visual>
    <collision>
      <origin rpy="0 0 0" xyz="0 0 0"/>
      <geometry>
        <mesh filename="package://doris_arm_description/meshes/roll_link.STL"/>
      </geometry>
    </collision>
  </link>
  <joint name="roll_joint" type="continuous">
    <origin rpy="1.5708 0.012731 3.1416" xyz="0 0 0"/>
    <parent link="elbow_link"/>
    <child link="roll_link"/>
    <axis xyz="0 0 1"/>
    <limit effort="6.0" velocity="6.28"/>
    <dynamics damping="0.7" friction="1.0"/>
  </joint>
  <link name="yaw_link">
    <inertial>
      <origin rpy="0 0 0" xyz="4.05516357848967E-05 -0.0160211563366842 -0.000189877443412478"/>
      <mass value="0.0768058991199202"/>
      <inertia ixx="0.002" ixy="0.0" ixz="0.0" iyy="0.002" iyz="0.0" izz="0.002"/>
    </inertial>
    <visual>
      <origin rpy="0 0 0" xyz="0 0 0"/>
      <geometry>
        <mesh filename="package://doris_arm_description/meshes/yaw_link.STL"/>
      </geometry>
      <material name="">
        <color rgba="0.792156862745098 0.819607843137255 0.933333333333333 1"/>
      </material>
    </visual>
    <collision>
      <origin rpy="0 0 0" xyz="0 0 0"/>
      <geometry>
        <mesh filename="package://doris_arm_description/meshes/yaw_link.STL"/>
      </geometry>
    </collision>
  </link>
  <joint name="yaw_joint" type="continuous">
    <origin rpy="1.5708 0 1.5708" xyz="0 0 -0.166"/>
    <parent link="roll_link"/>
    <child link="yaw_link"/>
    <axis xyz="0 0 1"/>
    <limit effort="6.0" velocity="6.28"/>
    <dynamics damping="0.7" friction="1.0"/>
  </joint>
  <link name="roll_2_link">
    <inertial>
      <origin rpy="0 0 0" xyz="3.30999898656703E-07 -0.0146248804164249 0.0456383476057014"/>
      <mass value="0.15161780969895"/>
      <inertia ixx="0.002" ixy="0.0" ixz="0.0" iyy="0.002" iyz="0.0" izz="0.002"/>
    </inertial>
    <visual>
      <origin rpy="0 0 0" xyz="0 0 0"/>
      <geometry>
        <mesh filename="package://doris_arm_description/meshes/roll_2_link.STL"/>
      </geometry>
      <material name="">
        <color rgba="0.792156862745098 0.819607843137255 0.933333333333333 1"/>
      </material>
    </visual>
    <collision>
      <origin rpy="0 0 0" xyz="0 0 0"/>
      <geometry>
        <mesh filename="package://doris_arm_description/meshes/roll_2_link.STL"/>
      </geometry>
    </collision>
  </link>
  <joint name="roll_2_joint" type="continuous">
    <origin rpy="1.3649 1.5708 -0.2119" xyz="0 -0.054822 -0.00015038"/>
    <parent link="yaw_link"/>
    <child link="roll_2_link"/>
    <axis xyz="0 0 1"/>
    <limit effort="6.0" velocity="6.28"/>
    <dynamics damping="0.7" friction="1.0"/>
  </joint>
  <link name="gripper_link">
    <inertial>
      <origin rpy="0 0 0" xyz="0.0230127657229507 0.000126473527769386 0.00158449770655011"/>
      <mass value="0.0174078384350788"/>
      <inertia ixx="0.002" ixy="0.0" ixz="0.0" iyy="0.002" iyz="0.0" izz="0.002"/>
    </inertial>
    <visual>
      <origin rpy="0 0 0" xyz="0 0 0"/>
      <geometry>
        <mesh filename="package://doris_arm_description/meshes/gripper_link.STL"/>
      </geometry>
      <material name="">
        <color rgba="0.792156862745098 0.819607843137255 0.933333333333333 1"/>
      </material>
    </visual>
    <collision>
      <origin rpy="0 0 0" xyz="0 0 0"/>
      <geometry>
        <mesh filename="package://doris_arm_description/meshes/gripper_link.STL"/>
      </geometry>
    </collision>
  </link>
  <joint name="gripper_joint" type="fixed">
    <origin rpy="3.1416 0 -0.012731" xyz="-0.021958 0.00027834 0.10168"/>
    <parent link="roll_2_link"/>
    <child link="gripper_link"/>
    <axis xyz="0 0 0"/>
  </joint>
  <link name="left_finger_link">
    <inertial>
      <origin rpy="0 0 0" xyz="-2.5501E-07 -0.0020883 0.03999"/>
      <mass value="0.0083226"/>
      <inertia ixx="0.002" ixy="0.0" ixz="0.0" iyy="0.002" iyz="0.0" izz="0.002"/>
    </inertial>
    <visual>
      <origin rpy="0 0 0" xyz="0 0 0"/>
      <geometry>
        <mesh filename="package://doris_arm_description/meshes/left_finger_link.STL"/>
      </geometry>
      <material name="">
        <color rgba="0.79216 0.81961 0.93333 1"/>
      </material>
    </visual>
    <collision>
      <origin rpy="0 0 0" xyz="0 0 0"/>
      <geometry>
        <mesh filename="package://doris_arm_description/meshes/left_finger_link.STL"/>
      </geometry>
    </collision>
  </link>
  <joint name="left_finger_joint" type="continuous">
    <origin rpy="2.7793 0 1.5708" xyz="-0.038057 0 -0.0015128"/>
    <parent link="gripper_link"/>
    <child link="left_finger_link"/>
    <axis xyz="1 0 0"/>
    <limit effort="3.0" velocity="6.28"/>
    <dynamics damping="0.7" friction="1.0"/>
  </joint>
  <link name="right_finger_link">
    <inertial>
      <origin rpy="0 0 0" xyz="-2.55484871550249E-07 0.0123652457374703 0.0380876079681996"/>
      <mass value="0.00832263335631547"/>
      <inertia ixx="0.002" ixy="0.0" ixz="0.0" iyy="0.002" iyz="0.0" izz="0.002"/>
    </inertial>
    <visual>
      <origin rpy="0 0 0" xyz="0 0 0"/>
      <geometry>
        <mesh filename="package://doris_arm_description/meshes/right_finger_link.STL"/>
      </geometry>
      <material name="">
        <color rgba="0.792156862745098 0.819607843137255 0.933333333333333 1"/>
      </material>
    </visual>
    <collision>
      <origin rpy="0 0 0" xyz="0 0 0"/>
      <geometry>
        <mesh filename="package://doris_arm_description/meshes/right_finger_link.STL"/>
      </geometry>
    </collision>
  </link>
  <joint name="right_finger_joint" type="continuous">
    <origin rpy="-3.1378 0 -1.5708" xyz="0.081977 0 -0.0015128"/>
    <parent link="gripper_link"/>
    <child link="right_finger_link"/>
    <axis xyz="-1 0 0"/>
    <limit effort="3.0" velocity="6.28"/>
    <dynamics damping="0.7" friction="1.0"/>
  </joint>
  <link name="dorso_link">
    <inertial>
      <origin rpy="0 0 0" xyz="-0.049721 -0.0015664 0.52098"/>
      <mass value="5.8385"/>
      <inertia ixx="0.23511" ixy="2.2795E-05" ixz="0.00021828" iyy="0.24015" iyz="2.7987E-05" izz="0.022627"/>
    </inertial>
    <visual>
      <origin rpy="0 0 0" xyz="0 0 0"/>
      <geometry>
        <mesh filename="package://doris_dorso_description/meshes/dorso_link.STL"/>
      </geometry>
      <material name="">
        <color rgba="0.79216 0.81961 0.93333 1"/>
      </material>
    </visual>
    <collision>
      <origin rpy="0 0 0" xyz="0 0 0"/>
      <geometry>
        <mesh filename="package://doris_dorso_description/meshes/dorso_link.STL"/>
      </geometry>
    </collision>
  </link>
  <link name="head_link">
    <inertial>
      <origin rpy="0 0 0" xyz="0 0 0.1"/>
      <mass value="0.2"/>
      <inertia ixx="0.001" ixy="0" ixz="0" iyy="0.001" iyz="0" izz="0.001"/>
    </inertial>
    <visual>
      <origin rpy="0 0 0" xyz="0 0 0"/>
      <geometry>
        <mesh filename="package://doris_head_description/meshes/animatronicFace.stl" scale="0.001 0.001 0.001"/>
      </geometry>
      <material name="gray_material">
            </material>
    </visual>
    <collision>
      <origin rpy="0 0 0" xyz="0 0 0"/>
      <geometry>
        <mesh filename="package://doris_head_description/meshes/animatronicFace.stl" scale="0.001 0.001 0.001"/>
      </geometry>
    </collision>
  </link>
  <gazebo reference="head_link">
    <material>Gazebo/Gray</material>
  </gazebo>
  <!-- Measured from CAD file -->
  <link name="base_footprint"/>
  <joint name="base_joint" type="fixed">
    <child link="base_link"/>
    <parent link="base_footprint"/>
  </joint>
  <link name="gripper_ir_link"/>
  <joint name="gripper_ir_joint" type="fixed">
    <child link="gripper_ir_link"/>
    <parent link="gripper_link"/>
    <origin rpy="0 1.57 0" xyz="0.02 0 -0.01"/>
  </joint>
  <link name="frontal_caster_link">
    <inertial>
      <origin rpy="0 0 0" xyz="0 0 0"/>
      <mass value="0.1"/>
      <inertia ixx="0.001" ixy="0" ixz="0" iyy="0.001" iyz="0" izz="0.001"/>
    </inertial>
    <collision>
      <origin rpy="0 0 0" xyz="0 0 0"/>
      <geometry>
        <sphere radius="0.05"/>
      </geometry>
    </collision>
  </link>
  <joint name="frontal_caster_joint" type="fixed">
    <parent link="base_link"/>
    <child link="frontal_caster_link"/>
    <origin rpy="0 0 0" xyz="0.2 0 0"/>
  </joint>
  <link name="rear_caster_link">
    <inertial>
      <origin rpy="0 0 0" xyz="0 0 0"/>
      <mass value="0.1"/>
      <inertia ixx="0.001" ixy="0" ixz="0" iyy="0.001" iyz="0" izz="0.001"/>
    </inertial>
    <collision>
      <origin rpy="0 0 0" xyz="0 0 0"/>
      <geometry>
        <sphere radius="0.05"/>
      </geometry>
    </collision>
  </link>
  <joint name="rear_caster_joint" type="fixed">
    <parent link="base_link"/>
    <child link="rear_caster_link"/>
    <origin rpy="0 0 0" xyz="-0.2 0 0"/>
  </joint>
  <!--
    <xacro:hand ns="doris" rpy="0 0 1.570" xyz="0 0 0.1" connected_to="roll_2_link" safety_distance="0.00" use_cylinder_collision_model="false" />
    -->
  <joint name="base_link_dorso" type="fixed">
    <parent link="base_link"/>
    <child link="dorso_link"/>
    <origin rpy="0 0 0" xyz="0 0 0.28"/>
  </joint>
  <joint name="dorso_arm_base" type="prismatic">
    <parent link="dorso_link"/>
    <child link="arm_base_link"/>
    <origin rpy="0 0 0" xyz="0.20 0 0"/>
    <axis xyz="0 0 1"/>
    <limit effort="2000.0" lower="0.02" upper="0.6" velocity="0.5"/>
    <dynamics damping="0.5" friction="0.1"/>
  </joint>
  <link name="laser">
    <inertial>
      <mass value="1.1"/>
      <origin xyz="0 0 0"/>
      <inertia ixx="0.00307156543804" ixy="0.0" ixz="0.0" iyy="0.0031284904152700005" iyz="0.0" izz="0.00196432421427"/>
    </inertial>
    <visual>
      <origin rpy="0 0 0" xyz="0 0 0"/>
      <geometry>
        <!-- Origin of this mesh is the focal point of the LIDAR. -->
        <mesh filename="package://lms1xx/meshes/sick-lms1xx.dae"/>
      </geometry>
    </visual>
    <collision>
      <origin rpy="0 0 0" xyz="0 0 -0.05"/>
      <geometry>
        <box size="0.105 0.1 0.1"/>
      </geometry>
    </collision>
  </link>
  <gazebo reference="laser">
    <turnGravityOff>true</turnGravityOff>
    <sensor name="laser" type="ray">
      <pose>0 0 0 0 0 0</pose>
      <visualize>false</visualize>
      <update_rate>50</update_rate>
      <ray>
        <scan>
          <horizontal>
            <samples>720</samples>
            <resolution>1</resolution>
            <min_angle>-2.35619</min_angle>
            <max_angle>2.35619</max_angle>
          </horizontal>
        </scan>
        <range>
          <min>0.1</min>
          <max>30.0</max>
          <resolution>0.01</resolution>
        </range>
        <noise>
          <type>gaussian</type>
          <mean>0.0</mean>
          <stddev>0.001</stddev>
        </noise>
      </ray>
      <plugin filename="libgazebo_ros_laser.so" name="gazebo_ros_laser">
        <topicName>scan</topicName>
        <frameName>laser</frameName>
        <robotNamespace>/</robotNamespace>
      </plugin>
    </sensor>
  </gazebo>
  <joint name="laser_joint" type="fixed">
    <origin rpy="0 0 0" xyz="0.222 0 -0.07"/>
    <parent link="dorso_link"/>
    <child link="laser"/>
  </joint>
  <joint name="kinect2_joint" type="fixed">
    <origin rpy="0 0.348 0" xyz="0.23 0 0.82"/>
    <parent link="dorso_link"/>
    <child link="kinect2_link"/>
  </joint>
  <link name="kinect2_link">
    <inertial>
      <mass value="0.01"/>
      <origin xyz="0 0 0"/>
      <inertia ixx="4.9000000000000005e-06" ixy="0.0" ixz="0.0" iyy="4.9000000000000005e-06" iyz="0.0" izz="4.9000000000000005e-06"/>
    </inertial>
    <visual>
      <origin rpy="0 0 0" xyz="0 0 0"/>
      <geometry>
        <mesh filename="package://hector_sensors_description/meshes/kinect_camera/kinect_camera_simple.dae"/>
      </geometry>
    </visual>
    <collision>
      <origin rpy="0 0 0" xyz="0 0 0"/>
      <geometry>
        <mesh filename="package://hector_sensors_description/meshes/kinect_camera/kinect_camera_simple.stl"/>
      </geometry>
    </collision>
  </link>
  <joint name="kinect2_depth_joint" type="fixed">
    <origin rpy="0 0 0" xyz="0.0 -0.02 0.0"/>
    <parent link="kinect2_link"/>
    <child link="kinect2_depth_frame"/>
  </joint>
  <link name="kinect2_depth_frame"/>
  <joint name="kinect2_depth_optical_joint" type="fixed">
    <origin rpy="-1.5707963267948966 0.0 -1.5707963267948966" xyz="0 0 0"/>
    <parent link="kinect2_depth_frame"/>
    <child link="kinect2_depth_optical_frame"/>
  </joint>
  <link name="kinect2_depth_optical_frame"/>
  <joint name="kinect2_rgb_joint" type="fixed">
    <origin rpy="0 0 0" xyz="0.0 -0.0125 0.0"/>
    <parent link="kinect2_link"/>
    <child link="kinect2_rgb_frame"/>
  </joint>
  <link name="kinect2_rgb_frame"/>
  <joint name="kinect2_rgb_optical_joint" type="fixed">
    <origin rpy="-1.5707963267948966 0.0 -1.5707963267948966" xyz="0 0 0"/>
    <parent link="kinect2_rgb_frame"/>
    <child link="kinect2_rgb_optical_frame"/>
  </joint>
  <link name="kinect2_rgb_optical_frame"/>
  <gazebo reference="kinect2_depth_frame">
    <sensor name="kinect2" type="depth">
      <update_rate>20</update_rate>
      <camera>
        <horizontal_fov>1.0471975511965976</horizontal_fov>
        <image>
          <format>B8G8R8</format>
          <width>640</width>
          <height>480</height>
        </image>
        <clip>
          <near>0.05</near>
          <far>3</far>
        </clip>
      </camera>
      <plugin filename="libgazebo_ros_openni_kinect.so" name="kinect2_camera_controller">
        <imageTopicName>kinect2/rgb/image_raw</imageTopicName>
        <cameraInfoTopicName>kinect2/rgb/camera_info</cameraInfoTopicName>
        <depthImageTopicName>kinect2/depth/image_raw</depthImageTopicName>
        <depthImageCameraInfoTopicName>kinect2/depth/camera_info</depthImageCameraInfoTopicName>
        <pointCloudTopicName>kinect2/depth/points</pointCloudTopicName>
        <frameName>kinect2_depth_optical_frame</frameName>
      </plugin>
    </sensor>
  </gazebo>
  <!--
    <xacro:realsense_d435_camera_with_mount name="realsense" parent="roll_2_link">
        <origin xyz="0 0.03 0.1" rpy="-1.570 -1.570 0" />
    </xacro:realsense_d435_camera_with_mount>
    -->
  <joint name="dorso_head" type="fixed">
    <parent link="dorso_link"/>
    <child link="head_link"/>
    <origin rpy="0 0 0" xyz="0 0 1.16"/>
  </joint>
  <joint name="hokuyo_joint" type="fixed">
    <origin rpy="3.14 0 0" xyz="0.32 0 0"/>
    <parent link="base_link"/>
    <child link="hokuyo_frame"/>
  </joint>
  <link name="hokuyo_frame">
    <inertial>
      <mass value="0.270"/>
      <origin rpy="0 0 0" xyz="0 0 0"/>
      <inertia ixx="2.632e-4" ixy="0" ixz="0" iyy="2.632e-4" iyz="0" izz="1.62e-4"/>
    </inertial>
    <visual>
      <origin rpy="0 0 0" xyz="0 0 0"/>
      <geometry>
        <mesh filename="package://hector_sensors_description/meshes/hokuyo_utm30lx/hokuyo_utm_30lx.dae"/>
      </geometry>
    </visual>
    <collision>
      <origin rpy="0 0 0" xyz="0 0 -0.0115"/>
      <geometry>
        <box size="0.058 0.058 0.087"/>
        <!--<mesh filename="package://hector_sensors_description/meshes/hokuyo_utm30lx/hokuyo_utm_30lx.stl"/>-->
      </geometry>
    </collision>
  </link>
  <gazebo reference="hokuyo_frame">
    <sensor name="hokuyo" type="ray">
      <always_on>true</always_on>
      <update_rate>30</update_rate>
      <pose>0 0 0 0 0 0</pose>
      <visualize>false</visualize>
      <ray>
        <scan>
          <horizontal>
            <samples>500</samples>
            <resolution>1</resolution>
            <min_angle>-1.5707963267948966</min_angle>
            <max_angle>1.5707963267948966</max_angle>
          </horizontal>
        </scan>
        <range>
          <min>0.2</min>
          <max>30.0</max>
          <resolution>0.01</resolution>
        </range>
        <noise>
          <type>gaussian</type>
          <mean>0.0</mean>
          <stddev>0.004</stddev>
        </noise>
      </ray>
      <plugin filename="libgazebo_ros_laser.so" name="gazebo_ros_hokuyo_controller">
        <topicName>scan2</topicName>
        <frameName>hokuyo_frame</frameName>
      </plugin>
    </sensor>
  </gazebo>
  <transmission name="trans_left_wheel_joint">
    <type>transmission_interface/SimpleTransmission</type>
    <joint name="left_wheel_joint">
      <hardwareInterface>hardware_interface/EffortJointInterface</hardwareInterface>
    </joint>
    <actuator name="left_wheel_joint_motor">
      <hardwareInterface>hardware_interface/EffortJointInterface</hardwareInterface>
      <mechanicalReduction>1</mechanicalReduction>
    </actuator>
  </transmission>
  <transmission name="trans_dorso_arm_base_joint">
    <type>transmission_interface/SimpleTransmission</type>
    <joint name="dorso_arm_base">
      <hardwareInterface>hardware_interface/EffortJointInterface</hardwareInterface>
    </joint>
    <actuator name="dorso_arm_linear_actuator">
      <hardwareInterface>hardware_interface/EffortJointInterface</hardwareInterface>
      <mechanicalReduction>1</mechanicalReduction>
    </actuator>
  </transmission>
  <transmission name="trans_right_wheel_joint">
    <type>transmission_interface/SimpleTransmission</type>
    <joint name="right_wheel_joint">
      <hardwareInterface>hardware_interface/EffortJointInterface</hardwareInterface>
    </joint>
    <actuator name="right_wheel_joint_motor">
      <hardwareInterface>hardware_interface/EffortJointInterface</hardwareInterface>
      <mechanicalReduction>1</mechanicalReduction>
    </actuator>
  </transmission>
  <transmission name="trans_shoulder_joint">
    <type>transmission_interface/SimpleTransmission</type>
    <joint name="shoulder_joint">
      <hardwareInterface>hardware_interface/EffortJointInterface</hardwareInterface>
    </joint>
    <actuator name="shoulder_joint_motor">
      <hardwareInterface>hardware_interface/EffortJointInterface</hardwareInterface>
      <mechanicalReduction>5</mechanicalReduction>
    </actuator>
  </transmission>
  <transmission name="trans_forearm_shoulder_joint">
    <type>transmission_interface/SimpleTransmission</type>
    <joint name="forearm_shoulder_joint">
      <hardwareInterface>hardware_interface/EffortJointInterface</hardwareInterface>
    </joint>
    <actuator name="forearm_shoulder_joint_motor">
      <hardwareInterface>hardware_interface/EffortJointInterface</hardwareInterface>
      <mechanicalReduction>5</mechanicalReduction>
    </actuator>
  </transmission>
  <transmission name="trans_elbow_joint">
    <type>transmission_interface/SimpleTransmission</type>
    <joint name="elbow_joint">
      <hardwareInterface>hardware_interface/EffortJointInterface</hardwareInterface>
    </joint>
    <actuator name="elbow_joint_motor">
      <hardwareInterface>hardware_interface/EffortJointInterface</hardwareInterface>
      <mechanicalReduction>5</mechanicalReduction>
    </actuator>
  </transmission>
  <transmission name="trans_roll_joint">
    <type>transmission_interface/SimpleTransmission</type>
    <joint name="roll_joint">
      <hardwareInterface>hardware_interface/EffortJointInterface</hardwareInterface>
    </joint>
    <actuator name="roll_joint_motor">
      <hardwareInterface>hardware_interface/EffortJointInterface</hardwareInterface>
      <mechanicalReduction>5</mechanicalReduction>
    </actuator>
  </transmission>
  <transmission name="trans_yaw_joint">
    <type>transmission_interface/SimpleTransmission</type>
    <joint name="yaw_joint">
      <hardwareInterface>hardware_interface/EffortJointInterface</hardwareInterface>
    </joint>
    <actuator name="yaw_joint_motor">
      <hardwareInterface>hardware_interface/EffortJointInterface</hardwareInterface>
      <mechanicalReduction>5</mechanicalReduction>
    </actuator>
  </transmission>
  <transmission name="trans_roll_2_joint">
    <type>transmission_interface/SimpleTransmission</type>
    <joint name="roll_2_joint">
      <hardwareInterface>hardware_interface/EffortJointInterface</hardwareInterface>
    </joint>
    <actuator name="roll_2_joint_motor">
      <hardwareInterface>hardware_interface/EffortJointInterface</hardwareInterface>
      <mechanicalReduction>5</mechanicalReduction>
    </actuator>
  </transmission>
  <!--
    <transmission name="trans_doris_finger_joint1">
        <type>transmission_interface/SimpleTransmission</type>
        <joint name="doris_finger_joint1">
            <hardwareInterface>hardware_interface/EffortJointInterface</hardwareInterface>
        </joint>
        <actuator name="doris_finger_joint1_motor">
            <hardwareInterface>hardware_interface/EffortJointInterface</hardwareInterface>
            <mechanicalReduction>1</mechanicalReduction>
        </actuator>
    </transmission>
    <transmission name="trans_doris_finger_joint2">
        <type>transmission_interface/SimpleTransmission</type>
        <joint name="doris_finger_joint2">
            <hardwareInterface>hardware_interface/EffortJointInterface</hardwareInterface>
        </joint>
        <actuator name="doris_finger_joint2_motor">
            <hardwareInterface>hardware_interface/EffortJointInterface</hardwareInterface>
            <mechanicalReduction>1</mechanicalReduction>
        </actuator>
    </transmission>-->
  <transmission name="trans_left_finger_joint">
    <type>transmission_interface/SimpleTransmission</type>
    <joint name="left_finger_joint">
      <hardwareInterface>hardware_interface/EffortJointInterface</hardwareInterface>
    </joint>
    <actuator name="left_finger_joint_motor">
      <hardwareInterface>hardware_interface/EffortJointInterface</hardwareInterface>
      <mechanicalReduction>5</mechanicalReduction>
    </actuator>
  </transmission>
  <transmission name="trans_right_finger_joint">
    <type>transmission_interface/SimpleTransmission</type>
    <joint name="right_finger_joint">
      <hardwareInterface>hardware_interface/EffortJointInterface</hardwareInterface>
    </joint>
    <actuator name="right_finger_joint_motor">
      <hardwareInterface>hardware_interface/EffortJointInterface</hardwareInterface>
      <mechanicalReduction>5</mechanicalReduction>
    </actuator>
  </transmission>
  <gazebo>
    <plugin filename="libgazebo_ros_control.so" name="gazebo_ros_control">
      <robotNamespace>/</robotNamespace>
    </plugin>
  </gazebo>
  <transmission name="trans_left_wheel_joint">
    <type>transmission_interface/SimpleTransmission</type>
    <joint name="left_wheel_joint">
      <hardwareInterface>hardware_interface/EffortJointInterface</hardwareInterface>
    </joint>
    <actuator name="left_wheel_joint_motor">
      <hardwareInterface>hardware_interface/EffortJointInterface</hardwareInterface>
      <mechanicalReduction>1</mechanicalReduction>
    </actuator>
  </transmission>
  <transmission name="trans_right_wheel_joint">
    <type>transmission_interface/SimpleTransmission</type>
    <joint name="right_wheel_joint">
      <hardwareInterface>hardware_interface/EffortJointInterface</hardwareInterface>
    </joint>
    <actuator name="right_wheel_joint_motor">
      <hardwareInterface>hardware_interface/EffortJointInterface</hardwareInterface>
      <mechanicalReduction>1</mechanicalReduction>
    </actuator>
  </transmission>
  <gazebo>
    <plugin filename="libgazebo_ros_diff_drive.so" name="differential_drive_controller">
      <!-- Plugin update rate in Hz -->
      <updateRate>50</updateRate>
      <!-- Name of left joint, defaults to `left_joint` -->
      <leftJoint>left_wheel_joint</leftJoint>
      <!-- Name of right joint, defaults to `right_joint` -->
      <rightJoint>right_wheel_joint</rightJoint>
      <!-- The distance from the center of one wheel to the other, in meters, defaults to 0.34 m -->
      <wheelSeparation>0.31</wheelSeparation>
      <!-- Diameter of the wheels, in meters, defaults to 0.15 m -->
      <wheelDiameter>0.2</wheelDiameter>
      <!-- Wheel acceleration, in rad/s^2, defaults to 0.0 rad/s^2 -->
      <wheelAcceleration>1.0</wheelAcceleration>
      <!-- Maximum torque which the wheels can produce, in Nm, defaults to 5 Nm -->
      <wheelTorque>20</wheelTorque>
      <!-- Topic to receive geometry_msgs/Twist message commands, defaults to `cmd_vel` -->
      <commandTopic>cmd_vel</commandTopic>
      <!-- Topic to publish nav_msgs/Odometry messages, defaults to `odom` -->
      <odometryTopic>odom</odometryTopic>
      <!-- Odometry frame, defaults to `odom` -->
      <odometryFrame>odom</odometryFrame>
      <!-- Robot frame to calculate odometry from, defaults to `base_footprint` -->
      <robotBaseFrame>base_footprint</robotBaseFrame>
      <!-- Odometry source, 0 for ENCODER, 1 for WORLD, defaults to WORLD -->
      <odometrySource>1</odometrySource>
      <!-- Set to true to publish transforms for the wheel links, defaults to false -->
      <publishWheelTF>false</publishWheelTF>
      <!-- Set to true to publish transforms for the odometry, defaults to true -->
      <publishOdom>true</publishOdom>
      <!-- Set to true to publish sensor_msgs/JointState on /joint_states for the wheel joints, defaults to false -->
      <publishWheelJointState>false</publishWheelJointState>
      <!-- Set to true to swap right and left wheels, defaults to true -->
      <legacyMode>false</legacyMode>
    </plugin>
  </gazebo>
  <material name="gray_material">
    <color rgba="0.5 0.5 0.5 1.0"/>
  </material>
  <material name="black_material">
    <color rgba="0.1 0.1 0.1 1.0"/>
  </material>
  <gazebo reference="base_link">
    <material>Gazebo/Gray</material>
  </gazebo>
  <gazebo reference="left_wheel_link">
    <material>Gazebo/DarkGray</material>
    <mu1>0.2</mu1>
    <mu2>0.2</mu2>
  </gazebo>
  <gazebo reference="right_wheel_link">
    <material>Gazebo/DarkGray</material>
    <mu1>0.2</mu1>
    <mu2>0.2</mu2>
  </gazebo>
  <gazebo reference="frontal_caster_link">
    <mu1>0.0001</mu1>
    <mu2>0.0001</mu2>
  </gazebo>
  <gazebo reference="rear_caster_link">
    <mu1>0.0001</mu1>
    <mu2>0.0001</mu2>
  </gazebo>
  <gazebo reference="dorso_link">
    <material>Gazebo/DarkGray</material>
  </gazebo>
  <gazebo reference="arm_base_link">
    <material>Gazebo/DarkGray</material>
  </gazebo>
  <gazebo reference="shoulder_link">
    <material>Gazebo/DarkGray</material>
  </gazebo>
  <gazebo reference="forearm_link">
    <material>Gazebo/DarkGray</material>
  </gazebo>
  <gazebo reference="elbow_link">
    <material>Gazebo/DarkGray</material>
  </gazebo>
  <gazebo reference="roll_link">
    <material>Gazebo/DarkGray</material>
  </gazebo>
  <gazebo reference="yaw_link">
    <material>Gazebo/DarkGray</material>
  </gazebo>
  <gazebo reference="roll_2_link">
    <material>Gazebo/DarkGray</material>
  </gazebo>
  <gazebo reference="gripper_link">
    <material>Gazebo/DarkGray</material>
    <mu1>10000.0</mu1>
    <mu2>100000.0</mu2>
    <min_depth>0.1</min_depth>
  </gazebo>
  <gazebo reference="left_finger_link">
    <material>Gazebo/Gray</material>
    <mu1>10000.0</mu1>
    <mu2>100000.0</mu2>
    <min_depth>0.1</min_depth>
  </gazebo>
  <gazebo reference="right_finger_link">
    <material>Gazebo/Gray</material>
    <mu1>10000.0</mu1>
    <mu2>100000.0</mu2>
    <min_depth>0.1</min_depth>
  </gazebo>
  <!--gazebo>
        <plugin name="gazebo_grasp_fix" filename="libgazebo_grasp_fix.so">
            <arm>
                <arm_name>arm</arm_name>
                <palm_link>roll_2_link</palm_link>
                <gripper_link>left_finger_link</gripper_link>
                <gripper_link>right_finger_link</gripper_link>
            </arm>
            <forces_angle_tolerance>100</forces_angle_tolerance>
            <update_rate>4</update_rate>
            <grip_count_threshold>4</grip_count_threshold>
            <max_grip_count>4</max_grip_count>
            <release_tolerance>0.005</release_tolerance>
            <disable_collisions_on_attach>false</disable_collisions_on_attach>
            <contact_topic>__default_topic__</contact_topic>
        </plugin>
    </gazeb-->
  <gazebo reference="gripper_ir_link">
    <sensor name="ir_gripper" type="ray">
      <pose>0 0 0 0 0 0</pose>
      <update_rate>50</update_rate>
      <ray>
        <scan>
          <horizontal>
            <samples>1</samples>
            <resolution>1.0</resolution>
            <min_angle>-0.08</min_angle>
            <max_angle>0.08</max_angle>
          </horizontal>
          <vertical>
            <samples>1</samples>
            <resolution>1</resolution>
            <min_angle>-0.04</min_angle>
            <max_angle>0.04</max_angle>
          </vertical>
        </scan>
        <range>
          <min>0.01</min>
          <max>1.5</max>
          <resolution>0.002</resolution>
        </range>
      </ray>
      <plugin filename="libgazebo_ros_range.so" name="gazebo_ros_range">
        <selfCollide>false</selfCollide>
        <alwaysOn>true</alwaysOn>
        <updateRate>5</updateRate>
        <topicName>/gripper/range</topicName>
        <frameName>ir_gripper</frameName>
        <visualize>false</visualize>
        <radiation>infrared</radiation>
        <fov>0.8</fov>
      </plugin>
    </sensor>
  </gazebo>
  <gazebo reference="left_finger_link">
    <sensor name="left_finger_bumper" type="contact">
      <selfCollide>false</selfCollide>
      <alwaysOn>true</alwaysOn>
      <updateRate>50.0</updateRate>
      <contact>
        <collision>left_finger_link_collision</collision>
      </contact>
      <plugin filename="libgazebo_ros_bumper.so" name="left_finger_ros_bumper_controller">
        <bumperTopicName>/gripper/contact/left</bumperTopicName>
        <frameName>world</frameName>
      </plugin>
    </sensor>
  </gazebo>
  <gazebo reference="right_finger_link">
    <sensor name="right_finger_bumper" type="contact">
      <selfCollide>false</selfCollide>
      <alwaysOn>true</alwaysOn>
      <updateRate>50.0</updateRate>
      <contact>
        <collision>right_finger_link_collision</collision>
      </contact>
      <plugin filename="libgazebo_ros_bumper.so" name="right_finger_ros_bumper_controller">
        <bumperTopicName>/gripper/contact/right</bumperTopicName>
        <frameName>world</frameName>
      </plugin>
    </sensor>
  </gazebo>
  <!--
    <gazebo reference="doris_hand">
        <material>Gazebo/DarkGray</material>
    </gazebo>
    <gazebo reference="doris_leftfinger">
        <material>Gazebo/Gray</material>
        <mu1>100.0</mu1>
        <mu2>100.0</mu2>
    </gazebo>
    <gazebo reference="doris_rightfinger">
        <material>Gazebo/Gray</material>
        <mu1>100.0</mu1>
        <mu2>100.0</mu2>
    </gazebo>-->
  <mujoco>
    <compiler balanceinertia="true" meshdir="../meshes"/>
  </mujoco>
</robot>

