<mujoco model="doris">
    <body mocap="true" name="robot0:mocap" pos="0 0 0">
        <geom conaffinity="0" contype="0" pos="0 0 0" rgba="0 0.5 0 0.7" size="0.005 0.005 0.005" type="box"></geom>
        <geom conaffinity="0" contype="0" pos="0 0 0" rgba="0 0.5 0 0.1" size="1 0.005 0.005" type="box"></geom>
        <geom conaffinity="0" contype="0" pos="0 0 0" rgba="0 0.5 0 0.1" size="0.005 1 0.001" type="box"></geom>
        <geom conaffinity="0" contype="0" pos="0 0 0" rgba="0 0.5 0 0.1" size="0.005 0.005 1" type="box"></geom>
    </body>
    <body name="base_link" pos="0.6 0.75 0.05">
        <geom type="mesh" rgba="0.79216 0.81961 0.93333 1" mesh="hull" />
        <geom size="0.05" pos="0.2 0 0" />
        <geom size="0.05" pos="-0.2 0 0" />
        <geom pos="0 0 0.28" type="mesh" rgba="0.79216 0.81961 0.93333 1" mesh="dorso_link" />
        <geom size="0.0525 0.05 0.05" pos="0.222 0 0.16" type="box" />
        <geom pos="0.23 0 1.1" quat="0.9849 0 0.173123 0" type="mesh" mesh="kinect_camera_simple" />
        <geom pos="0 0 1.44" type="mesh" mesh="animatronicFace" />
        <geom size="0.029 0.029 0.0435" pos="0.32 1.83155e-05 0.0115" quat="0.000796327 1 0 0" type="box" />
        <body name="left_wheel_link" pos="0 0.1415 0.0495" quat="0.500897 0.499099 0.499101 0.500899">
            <inertial pos="0.0375 0 0" mass="2.1507" diaginertia="0.0099942 0.0058914 0.0058914" />
            <joint name="left_wheel_joint" pos="0 0 0" axis="1 0 0" />
            <geom type="mesh" rgba="0.79216 0.81961 0.93333 1" mesh="left_wheel_link" />
        </body>
        <body name="right_wheel_link" pos="0 -0.1787 0.0495" quat="0.657307 0.260664 0.260665 0.657309">
            <inertial pos="-0.00029672 0 0" mass="2.1507" diaginertia="0.0099942 0.0058914 0.0058914" />
            <joint name="right_wheel_joint" pos="0 0 0" axis="1 0 0" />
            <geom type="mesh" rgba="0.79216 0.81961 0.93333 1" mesh="right_wheel_link" />
        </body>
        <body name="arm_base_link" pos="0.2 0 0.28">
            <inertial pos="0.0032335 -3.6289e-06 0.02346" mass="0.086496" diaginertia="0.002 0.002 0.002" />
            <joint name="dorso_arm_base" pos="0 0 0" axis="0 0 1" type="slide" limited="true" range="0.02 0.6" damping="0.5" frictionloss="10.0" />
            <geom type="mesh" rgba="0.79216 0.81961 0.93333 1" mesh="arm_base_link" />
            <body name="shoulder_link" pos="0.018961 0 0.049" quat="0.707105 0.707108 0 0">
                <inertial pos="1.80019e-06 0.0469908 1.02798e-05" mass="0.187372" diaginertia="0.002 0.002 0.002" />
                <joint name="shoulder_joint" pos="0 0 0" axis="0 1 0" damping="0.7" frictionloss="1" />
                <geom type="mesh" rgba="0.792157 0.819608 0.933333 1" mesh="shoulder_link" />
                <body name="forearm_link" pos="0 0.0656 0" quat="0.484973 0.514587 0.484976 -0.514587">
                    <inertial pos="-1.08639e-05 0.145958 0.00428435" mass="0.0731492" diaginertia="0.002 0.002 0.002" />
                    <joint name="forearm_shoulder_joint" pos="0 0 0" axis="1 0 0" damping="0.7" frictionloss="1" />
                    <geom type="mesh" rgba="0.792157 0.819608 0.933333 1" mesh="forearm_link" />
                    <body name="elbow_link" pos="0 0.30821 -0.040455" quat="0.648228 0.282487 -0.64823 -0.282487">
                        <inertial pos="-3.11104e-05 -0.0168263 0.000457294" mass="0.0892046" diaginertia="0.002 0.002 0.002" />
                        <joint name="elbow_joint" pos="0 0 0" axis="0 0 1" damping="0.7" frictionloss="1" />
                        <geom type="mesh" rgba="0.792157 0.819608 0.933333 1" mesh="elbow_link" />
                        <body name="roll_link" pos="0 0 0" quat="0.00449847 -0.00450365 0.707094 0.707091">
                            <inertial pos="1.1912e-08 -0.0100837 -0.0945596" mass="0.108645" diaginertia="0.002 0.002 0.002" />
                            <joint name="roll_joint" pos="0 0 0" axis="0 0 1" damping="0.7" frictionloss="1" />
                            <geom type="mesh" rgba="0.792157 0.819608 0.933333 1" mesh="roll_link" />
                            <body name="yaw_link" pos="0 0 -0.166" quat="0.499998 0.5 0.500002 0.5">
                                <inertial pos="4.05516e-05 -0.0160212 -0.000189877" mass="0.0768059" diaginertia="0.002 0.002 0.002" />
                                <joint name="yaw_joint" pos="0 0 0" axis="0 0 1" damping="0.7" frictionloss="1" />
                                <geom type="mesh" rgba="0.792157 0.819608 0.933333 1" mesh="yaw_link" />
                                <body name="roll_2_link" pos="0 -0.054822 -0.00015038" quat="0.498496 0.501498 0.498498 -0.501499">
                                    <inertial pos="0.000108569 -0.0131332 0.0512469" quat="0.991522 -0.129603 0.00924537 -0.00120847" mass="0.169026" diaginertia="0.0040496 0.0040496 0.004" />
                                    <joint name="roll_2_joint" pos="0 0 0" axis="0 0 1" damping="0.7" frictionloss="1" />
                                    <geom type="mesh" rgba="0.792157 0.819608 0.933333 1" mesh="roll_2_link" />
                                    <geom pos="-0.021958 0.00027834 0.10168" quat="-3.67313e-06 0.99998 -0.00636546 2.33816e-08" type="mesh" rgba="0.792157 0.819608 0.933333 1" mesh="gripper_link" condim="4" friction="1.0" />
                                    <body name="left_finger_link" pos="-0.0600119 0.000762819 0.103193" quat="-0.691095 0.126574 -0.128202 0.699951">
                                        <inertial pos="-2.5501e-07 -0.0020883 0.03999" mass="0.0083226" diaginertia="0.002 0.002 0.002" />
                                        <joint name="left_finger_joint" pos="0 0 0" axis="1 0 0" damping="0.7" frictionloss="1" />
                                        <geom type="mesh" rgba="0.79216 0.81961 0.93333 1" mesh="left_finger_link" condim="4" friction="1.0" />
                                    </body>
                                    <body name="right_finger_link" pos="0.0600124 -0.000765292 0.103193" quat="0.711591 0.00135199 0.00132973 0.702591">
                                        <inertial pos="-2.55485e-07 0.0123652 0.0380876" mass="0.00832263" diaginertia="0.002 0.002 0.002" />
                                        <joint name="right_finger_joint" pos="0 0 0" axis="1 0 0" damping="0.7" frictionloss="1" />
                                        <geom type="mesh" rgba="0.792157 0.819608 0.933333 1" mesh="right_finger_link" condim="4" friction="1.0" />
                                    </body>
                                    <site name="robot0:grip" pos="0 0 0.1" rgba="0 0 0 0" size="0.02 0.02 0.02"></site>
                                </body>
                            </body>
                        </body>
                    </body>
                </body>
            </body>
        </body>
    </body>
</mujoco>
